<?xml version="1.0"?>
<robot xmlns:xacro="http://www.ros.org/wiki/xacro">

  <link name="base_footprint"/>

  <link name="base_link">

    <inertial>
      <origin xyz="0 0 0.09424" rpy="0 0 0"/>
      <mass value="3"/>
      <inertia ixx="0.00783" ixy="0.0" ixz="0.0"
               iyy="0.01741" iyz="0.0"
               izz="0.01803"/>
    </inertial>

    <visual>
      <origin xyz="0 0 0.09424" rpy="0 0 0"/>
      <geometry>
        <box size="0.235 0.130 0.12"/>
      </geometry>
      <material name="chassis_grey">
        <color rgba="0.3 0.3 0.3 1.0"/>
      </material>
    </visual>

    <collision>
      <origin xyz="0 0 0.09424" rpy="0 0 0"/>
      <geometry>
        <box size="0.235 0.130 0.12"/>
      </geometry>
    </collision>
  </link>


  <joint name="base_footprint_to_base_link" type="fixed">
    <parent link="base_footprint"/>
    <child link="base_link"/>
    <origin xyz="0 0 0" rpy="0 0 0"/>
  </joint>


  <!-- ================= WHEELS MACRO ================= -->
  <xacro:macro name="wheel" params="name x y">
    <link name="${name}_link">
      <visual>
        <geometry>
          <cylinder radius="0.03725" length="0.02"/>
        </geometry>

        <material name="wheel_black">
          <color rgba="0.0 0.0 0.0 1.0"/>
        </material>

        <origin xyz="0 0 0" rpy="1.57 0 0"/>
      </visual>

      <inertial>
        <origin xyz="0 0 0" rpy="0 0 0"/>
        <mass value="0.1"/>
        <inertia ixx="0.0001" ixy="0.0" ixz="0.0"
                 iyy="0.0001" iyz="0.0"
                 izz="0.0001"/>
      </inertial>

      <collision>
        <origin xyz="0 0 0" rpy="1.57 0 0"/>
        <geometry>
          <cylinder radius="0.03725" length="0.02"/>
        </geometry>
      </collision>

    </link>

    <joint name="${name}_joint" type="continuous">
      <parent link="base_link"/>
      <child link="${name}_link"/>
      <origin xyz="${x} ${y} 0.03725" rpy= "0 0 0"/>
      <axis xyz="0 1 0"/>
    </joint>
  </xacro:macro>

  <!-- ================= WHEELS ================= -->
  <xacro:wheel name="wheel_fl" x="0.077" y="0.077"/>
  <xacro:wheel name="wheel_fr" x="0.077" y="-0.077"/>
  <xacro:wheel name="wheel_rl" x="-0.077" y="0.077"/>
  <xacro:wheel name="wheel_rr" x="-0.077" y="-0.077"/>


</robot>
