<?xml version="1.0"?>
<robot name="cobraflex_mav1" xmlns:xacro="http://www.ros.org/wiki/xacro">

  <link name="base_footprint">
    <visual>
      <origin xyz="0 0 0" rpy="0 0 0"/>
      <geometry>
        <sphere radius="0.001"/>
      </geometry>
      <material name="invisible">
        <color rgba="0 0 0 0"/>
      </material>
    </visual>
  </link>

  <link name="base_link">

    <inertial>
      <origin xyz="0 0 0.09424" rpy="0 0 0"/>
      <mass value="3"/>
      <inertia ixx="0.00783" ixy="0.0" ixz="0.0"
               iyy="0.01741" iyz="0.0"
               izz="0.01803"/>
    </inertial>

    <visual>
      <origin xyz="0 0 0.09424" rpy="0 0 0"/>
      <geometry>
        <box size="0.235 0.130 0.12"/>
      </geometry>
      <material name="chassis_grey">
        <color rgba="0.3 0.3 0.3 1.0"/>
      </material>
    </visual>

    <collision>
      <origin xyz="0 0 0.09424" rpy="0 0 0"/>
      <geometry>
        <box size="0.235 0.130 0.12"/>
      </geometry>
    </collision>
  </link>


  <joint name="base_footprint_to_base_link" type="fixed">
    <parent link="base_footprint"/>
    <child link="base_link"/>
    <origin xyz="0 0 0" rpy="0 0 0"/>
  </joint>


  <link name="wheel_fl">
    <visual>
      <origin xyz="0 0 0" rpy="1.5708 0 0"/>
      <geometry>
        <cylinder radius="0.03725" length="0.02"/>
      </geometry>
      <material name="wheel_black">
        <color rgba="0.05 0.05 0.05 1.0"/>
      </material>
    </visual>
    <collision>
      <origin xyz="0 0 0" rpy="1.5708 0 0"/>
      <geometry>
        <cylinder radius="0.03725" length="0.02"/>
      </geometry>
    </collision>
    <inertial> 
      <origin xyz="0 0 0" rpy="0 0 0"/>
      <mass value="0.1"/>
      <inertia ixx="0.0001" ixy="0.0" ixz="0.0"
               iyy="0.0001" iyz="0.0"
               izz="0.0001"/>
    </inertial> 
  </link>


  <link name="wheel_fr">
    <visual>
      <origin xyz="0 0 0" rpy="1.5708 0 0"/>
      <geometry>
        <cylinder radius="0.03725" length="0.02"/>
      </geometry>
      <material name="wheel_black"/>
    </visual>
    <collision>
      <origin xyz="0 0 0" rpy="1.5708 0 0"/>
      <geometry>
        <cylinder radius="0.03725" length="0.02"/>
      </geometry>
    </collision>
    <inertial> 
      <origin xyz="0 0 0" rpy="0 0 0"/>
      <mass value="0.1"/>
      <inertia ixx="0.0001" ixy="0.0" ixz="0.0"
               iyy="0.0001" iyz="0.0"
               izz="0.0001"/>
    </inertial>
  </link>

  <link name="wheel_rl">
    <visual>
      <origin xyz="0 0 0" rpy="1.5708 0 0"/>
      <geometry>
        <cylinder radius="0.03725" length="0.02"/>
      </geometry>
      <material name="wheel_black"/>
    </visual>
    <collision>
      <origin xyz="0 0 0" rpy="1.5708 0 0"/>
      <geometry>
        <cylinder radius="0.03725" length="0.02"/>
      </geometry>
    </collision>
    <inertial> 
      <origin xyz="0 0 0" rpy="0 0 0"/>
      <mass value="0.1"/>
      <inertia ixx="0.0001" ixy="0.0" ixz="0.0"
               iyy="0.0001" iyz="0.0"
               izz="0.0001"/>
    </inertial>
  </link>

  <link name="wheel_rr">
    <visual>
      <origin xyz="0 0 0" rpy="1.5708 0 0"/>
      <geometry>
        <cylinder radius="0.03725" length="0.02"/>
      </geometry>
      <material name="wheel_black"/>
    </visual>
    <collision>
      <origin xyz="0 0 0" rpy="1.5708 0 0"/>
      <geometry>
        <cylinder radius="0.03725" length="0.02"/>
      </geometry>
    </collision>
    <inertial> 
      <origin xyz="0 0 0" rpy="0 0 0"/>
      <mass value="0.1"/>
      <inertia ixx="0.0001" ixy="0.0" ixz="0.0"
               iyy="0.0001" iyz="0.0"
               izz="0.0001"/>
    </inertial> 
  </link>


  <joint name="joint_wheel_fl" type="continuous">
    <parent link="base_link"/>
    <child link="wheel_fl"/>
    <origin xyz="0.077 0.077 0.03725" rpy="0 0 0"/>
    <axis xyz="0 1 0"/>
  </joint>


  <joint name="joint_wheel_fr" type="continuous">
    <parent link="base_link"/>
    <child link="wheel_fr"/>
    <origin xyz="0.077 -0.077 0.03725" rpy="0 0 0"/>
    <axis xyz="0 1 0"/>
  </joint>


  <joint name="joint_wheel_rl" type="continuous">
    <parent link="base_link"/>
    <child link="wheel_rl"/>
    <origin xyz="-0.077 0.077 0.03725" rpy="0 0 0"/>
    <axis xyz="0 1 0"/>
  </joint>


  <joint name="joint_wheel_rr" type="continuous">
    <parent link="base_link"/>
    <child link="wheel_rr"/>
    <origin xyz="-0.077 -0.077 0.03725" rpy="0 0 0"/>
    <axis xyz="0 1 0"/>
  </joint>


  <link name="base_laser">
    <visual>
      <origin xyz="0 0 0" rpy="0 0 0"/>
      <geometry>
        <cylinder radius="0.03" length="0.02"/>
      </geometry>
      <material name="rplidar_mat">
        <color rgba="0.2 0.2 0.2 1.0"/>
      </material>
    </visual>
    <collision>
      <origin xyz="0 0 0" rpy="0 0 0"/>
      <geometry>
        <cylinder radius="0.03" length="0.02"/>
      </geometry>
    </collision>
  </link>


  <joint name="base_link_to_laser" type="continuous">
    <parent link="base_link"/>
    <child link="base_laser"/>
    <origin xyz="0 0 0.165" rpy="0 0 0"/>
    <axis xyz="0 0 1"/>
  </joint>


  <link name="zed_camera_link">
    <visual>
      <origin xyz="0 0 0" rpy="0 0 0"/>
      <geometry>
        <box size="0.0305 0.124 0.0265"/>
      </geometry>
      <material name="zedm_mat">
        <color rgba="0 0 0 1.0"/>
      </material>
    </visual>
    <collision>
      <origin xyz="0 0 0" rpy="0 0 0"/>
      <geometry>
        <box size="0.0305 0.124 0.0265"/>
      </geometry>
    </collision>
  </link>

  <joint name="base_link_to_camera" type="fixed">
    <parent link="base_link"/>
    <child link="zed_camera_link"/>
    <origin xyz="0.10 0 0.13" rpy="0 0 0"/>
  </joint>

</robot>
